<?xml version="1.0"?>
<robot name="maccepa" xmlns:xacro="http://www.ros.org/wiki/xacro">

  <xacro:include filename="$(find maccepa_description)/urdf/materials.xacro" />
  <xacro:include filename="$(find maccepa_description)/urdf/link/maccepa_link.urdf.xacro"/>
  <xacro:include filename="$(find maccepa_description)/urdf/camdisk/maccepa_camdisk.urdf.xacro"/>
  <xacro:include filename="$(find maccepa_description)/gazebo/gazebo.urdf.xacro"/>

  <xacro:property name="link_length" value="0.25"/><!-- [m] -->
  <xacro:property name="link_mass" value="1"/><!-- [kg] -->
  <xacro:property name="camdisk_length" value="0.04"/><!-- [m] -->

  <link name="world"/>

  <!-- Dummy link holding robot base coordinate frame -->
  <link name="base">
    <inertial>
      <origin xyz="0 0 0" rpy="0 0 0"/>
      <mass value="1"/>
      <inertia ixx="0" ixy="0" ixz="0" iyy="0" iyz="0" izz="0"/>
    </inertial>
  </link>
  <joint name="world_to_base" type="fixed">
    <parent link="world"/>
    <child link="base"/>
    <origin xyz="0 0 0 " rpy="0 ${pi/2} 0" />
  </joint>

  <!-- First Link -->
  <maccepa_link name="arm" length="${link_length}" mass="${link_mass}" material="blue"/>
  <gazebo_blue reference="arm"/>
  <joint name="shoulder" type="revolute">
    <parent link="base"/>
    <child link="arm" />
    <limit
        lower="-10"
        upper="10"
        effort="1000"
        velocity="1000" />
    <origin xyz="0 0 0 " rpy="0 0 0" />
    <axis xyz="0 1 0" />
  </joint>

  <!-- Second Link -->
  <maccepa_link name="forearm" length="${link_length}" mass="${link_mass}" material="green"/>
  <gazebo_red reference="forearm"/>
  <joint name="elbow" type="revolute">
    <parent link="arm"/>
    <child link="forearm" />
    <limit
      lower="-10"
      upper="10"
      effort="1000"
      velocity="1000" />
    <origin xyz="0.25 0 0 " rpy="0 0 0" />
    <axis xyz="0 1 0" />
  </joint>

  <!-- Motors output shaft (visual only) -->
  <!-- First motor -->
  <maccepa_camdisk name="shoulder_motor" length="${camdisk_length}" material="red"/>
  <gazebo_yellow reference="shoulder_motor"/>
  <joint name="shoulder_motor_joint" type="revolute">
    <parent link="base"/>
    <child link="shoulder_motor" />
    <limit
        lower="-10"
        upper="10"
        effort="1000"
        velocity="1000" />
    <origin xyz="0 0.01 0 " rpy="0 0 0" />
    <axis xyz="0 1 0" />
  </joint>

  <!-- Second motor -->
  <maccepa_camdisk name="elbow_motor" length="${camdisk_length}" material="red"/>
  <gazebo_yellow reference="elbow_motor"/>
  <joint name="elbow_motor_joint" type="revolute">
    <parent link="arm"/>
    <child link="elbow_motor" />
    <limit
        lower="-10"
        upper="10"
        effort="1000"
        velocity="1000" />
    <origin xyz="0.25 0.01 0 " rpy="0 0 0" />
    <axis xyz="0 1 0" />
  </joint>

</robot>
